Workbook

Sheet lista
A1: orgao | B1: municipio | C1: numero_convenio | D1: ano | E1: objeto | F1: data_fim | G1: valor_total | H1: valor_contrapartida | I1: valor_orgao
A2: SEOP | B2: Abaetetuba | C2: 090/2022 | D2: =RIGHT(lista!$C2,4) -> 2022 | E2: REFORMA DE FEIRAS E REVITALIZAÇÃO DA ÁREA COMERCIAL POPULAR NO MUNICÍPIO DE ABAETETUBA, NESTE ESTADO | F2: 46386 | G2: =Tabela1[[#This Row],[valor_contrapartida]]+Tabela1[[#This Row],[valor_orgao]] -> 11015933 | H2: 1101593.3 | I2: 9914339.5
A3: SEOP | B3: Abaetetuba | C3: 247/2022 | D3: =RIGHT(lista!$C3,4) -> 2022 | E3: RECAPEAMENT O DE VIAS, NO MUNICÍPIO DE ABAETETUBA, NESTE ESTADO | F3: 46142 | G3: =Tabela1[[#This Row],[valor_contrapartida]]+Tabela1[[#This Row],[valor_orgao]] -> 12990053 | H3: 2990052.9 | I3: 10000000
A4: SEOP | B4: Abel Figueiredo | C4: 125/2022 | D4: =RIGHT(lista!$C4,4) -> 2022 | E4: REFORMA DA CÂMARA MUNICIPAL, NO MUNICÍPIO DE ABEL FIGUEIREDO | F4: 45457 | G4: =Tabela1[[#This Row],[valor_contrapartida]]+Tabela1[[#This Row],[valor_orgao]] -> 311899.45 | H4: 12475.98 | I4: 299423.47
A5: SEOP | B5: Abel Figueiredo | C5: 126/2022 | D5: =RIGHT(lista!$C5,4) -> 2022 | E5: URBANIZAÇÃO DAS LAGOAS DE ABEL FIGUEIREDO NESTE ESTADO | F5: 46056 | G5: =Tabela1[[#This Row],[valor_contrapartida]]+Tabela1[[#This Row],[valor_orgao]] -> 1601371.5 | H5: 101371.53 | I5: 1500000
A6: SEOP | B6: Abel Figueiredo | C6: 128/2022 | D6: =RIGHT(lista!$C6,4) -> 2022 | E6: REFORMA DO PRÉDIO DA PREFEITURA MUNICIPAL, NO MUNICÍPIO DE ABEL FIGUEIREDO | F6: 45465 | G6: =Tabela1[[#This Row],[valor_contrapartida]]+Tabela1[[#This Row],[valor_orgao]] -> 353408.85 | H6: 103408.85 | I6: 250000
A7: SEOP | B7: Abel Figueiredo | C7: 043/2024 | D7: =RIGHT(lista!$C7,4) -> 2024 | E7: CONSTRUÇÃO DA PRAÇA DA JUVENTUDE DE ABEL FIGUEIREDO, NO MUNICÍPIO DE ABEL FIGUEIREDO, NESTE ESTADO | F7: 46200 | G7: =Tabela1[[#This Row],[valor_contrapartida]]+Tabela1[[#This Row],[valor_orgao]] -> 1057368.7 | H7: 42294.75 | I7: 1015073.9
A8: SEOP | B8: Acará | C8: 006/2022 | D8: =RIGHT(lista!$C8,4) -> 2022 | E8: PAVIMENTAÇÃO DE VIAS EM BLOQUETES NA VILA SÃO LOURENÇO E VILA BOA ESPERANÇA, NO MUNICÍPIO DE ACARÁ, NESTE ESTADO | F8: 46204 | G8: =Tabela1[[#This Row],[valor_contrapartida]]+Tabela1[[#This Row],[valor_orgao]] -> 1050350.9 | H8: 52517.54 | I8: 997833.36
A9: SEOP | B9: Acará | C9: 089/2022 | D9: =RIGHT(lista!$C9,4) -> 2022 | E9: CONSTRUÇÃO E URBANIZAÇÃO DE ORLA DA CIDADE, NO MUNICÍPIO DE ACARÁ | F9: 46062 | G9: =Tabela1[[#This Row],[valor_contrapartida]]+Tabela1[[#This Row],[valor_orgao]] -> 6238801.8 | H9: 311940.09 | I9: 5926861.7
A10: SEOP | B10: Acará | C10: 048/2024 | D10: =RIGHT(lista!$C10,4) -> 2024 | E10: PAVIMENTAÇÃO DE VIAS EM BLOQUETES NA VILA PARQUE VITÓRIA E VILA VERA CRUZ, NO MUNICÍPIO DO ACARÁ, NESTE ESTADO | F10: 46201 | G10: =Tabela1[[#This Row],[valor_contrapartida]]+Tabela1[[#This Row],[valor_orgao]] -> 1673751.7 | H10: 673751.7 | I10: 1000000
A11: SEOP | B11: Afuá | C11: 049/2022 | D11: =RIGHT(lista!$C11,4) -> 2022 | E11: AMPLIAÇÃO DE REDE DE ABASTECIMENTO DE ÁGUA DO BAIRRO CAPIM MARINHO, MUNICÍPIO DE AFUÁ | F11: 45971 | G11: =Tabela1[[#This Row],[valor_contrapartida]]+Tabela1[[#This Row],[valor_orgao]] -> 7103939.8 | H11: 284157.59 | I11: 6819782.2
A12: SEOP | B12: Alenquer | C12: 012/2022 | D12: =RIGHT(lista!$C12,4) -> 2022 | E12: CONSTRUÇÃO DE COBERTURA DE QUADRA POLIESPORTIVA DO BAIRRO NOVA ESPERANÇA, NO MUNICÍPIO DE ALENQUER | F12: 45752 | G12: =Tabela1[[#This Row],[valor_contrapartida]]+Tabela1[[#This Row],[valor_orgao]] -> 391579.66 | H12: 39157.97 | I12: 352421.69
A13: SEOP | B13: Alenquer | C13: 020/2022 | D13: =RIGHT(lista!$C13,4) -> 2022 | E13: CONSTRUÇÃO DE COBERTURA DE QUADRA POLIESPORTIVA AUGUSTO CEZAR QUARESMA, NO MUNICÍPIO DE ALENQUER | F13: 46117 | G13: =Tabela1[[#This Row],[valor_contrapartida]]+Tabela1[[#This Row],[valor_orgao]] -> 391579.66 | H13: 39157.97 | I13: 352421.69
... A178: SEOP | B178: Medicilândia | C178: 004/2022 | D178: =RIGHT(lista!$C178,4) -> 2022 | E178: CONSTRUÇÃO DE COBERTURA DE QUADRA DO KM95 NORTE, EM MEDICILÂNDIA | F178: 45839 | G178: =Tabela1[[#This Row],[valor_contrapartida]]+Tabela1[[#This Row],[valor_orgao]] -> 410588.49 | H178: 16423.54 | I178: 394164.95
A179: SEOP | B179: Medicilândia | C179: 072/2022 | D179: =RIGHT(lista!$C179,4) -> 2022 | E179: EXECUÇÃO REFORMA E AMPLIAÇÃO DE QUADRA ESPORTIVA, NO MUNICÍPIO MEDICILÂNDIA | G179: =Tabela1[[#This Row],[valor_contrapartida]]+Tabela1[[#This Row],[valor_orgao]] -> 197260.48 | H179: 7890.41 | I179: 189370.07
A180: SEOP | B180: Medicilândia | C180: 120/2022 | D180: =RIGHT(lista!$C180,4) -> 2022 | E180: CONSTRUÇÃO DE DOIS (02) MICROSSISTEMAS DE ABASTECIMENTO DE AGUA LOCALIZADOS NAS COMUNIDADES DO KM 115 SUL E COMUNIDADE DO KM 85 NORTE, NO MUNICÍPIO DE MEDICILÂNDIA | F180: 45379 | G180: =Tabela1[[#This Row],[valor_contrapartida]]+Tabela1[[#This Row],[valor_orgao]] -> 197260.48 | H180: 7890.41 | I180: 189370.07
A181: SEOP | B181: Medicilândia | C181: 238/2022 | D181: =RIGHT(lista!$C181,4) -> 2022 | E181: CONSTRUÇÃO DE COBERTURA DA QUADRA DA AGROVILA JORGE BUENO, NO MUNICÍPIO DE MEDICILÂNDIA, NESTE ESTADO | F181: 45470 | G181: =Tabela1[[#This Row],[valor_contrapartida]]+Tabela1[[#This Row],[valor_orgao]] -> 439385.94 | H181: 17575.44 | I181: 421810.5
A182: SEOP | B182: Medicilândia | C182: 255/2022 | D182: =RIGHT(lista!$C182,4) -> 2022 | E182: PAVIMENTAÇÃO DE ACESSO AO PARQUE DE EXPOSIÇÃO UBALDINO KRUGUER KM 90 NORTE NO MUNICÍPIO DE MEDICILÂNDIA, NESTE ESTADO | F182: 46204 | G182: =Tabela1[[#This Row],[valor_contrapartida]]+Tabela1[[#This Row],[valor_orgao]] -> 8781563.9 | H182: 1428817.9 | I182: 7352746
A183: SEOP | B183: Mocajuba | C183: 029/2023 | D183: =RIGHT(lista!$C183,4) -> 2023 | E183: CONCLUSÃO DA CONSTRUÇÃO DO COMPLEXO MIRANTE DO BOTO NO MUNICÍPIO DE MOCAJUBA | F183: 45997 | G183: =Tabela1[[#This Row],[valor_contrapartida]]+Tabela1[[#This Row],[valor_orgao]] -> 2500042.9 | H183: 100002 | I183: 2400040.9
A184: SEOP | B184: Mojuí Dos Campos | C184: 084/2022 | D184: =RIGHT(lista!$C184,4) -> 2022 | E184: CONSTRUÇÃO DE QUADRA POLIESPORTIVA NA COMUNIDADE PIRANHA, NO MUNICÍPIO DE MOJUÍ DOS CAMPOS | F184: 45687 | G184: =Tabela1[[#This Row],[valor_contrapartida]]+Tabela1[[#This Row],[valor_orgao]] -> 276555.21 | H184: 76555.21 | I184: 200000
A185: SEOP | B185: Mojuí Dos Campos | C185: 198/2022 | D185: =RIGHT(lista!$C185,4) -> 2022 | E185: CONSTRUÇÃO DO GINÁSIO POLIESPORTIVO NO MUNICÍPIO DE MOJUÍ DOS CAMPOS | F185: 46194 | G185: =Tabela1[[#This Row],[valor_contrapartida]]+Tabela1[[#This Row],[valor_orgao]] -> 2717774.5 | H185: 108710.99 | I185: 2609063.5
A186: SEOP | B186: Mojuí Dos Campos | C186: 259/2022 | D186: =RIGHT(lista!$C186,4) -> 2022 | E186: CONSTRUÇÃO DE UMA PRAÇA, NO MUNICÍPIO DE MOJUI DOS CAMPOS - PA, NESTE ESTADO | F186: 46203 | G186: =Tabela1[[#This Row],[valor_contrapartida]]+Tabela1[[#This Row],[valor_orgao]] -> 2166334.7 | H186: 266334.74 | I186: 1900000
A187: SEOP | B187: Mojuí Dos Campos | C187: 294/2022 | D187: =RIGHT(lista!$C187,4) -> 2022 | E187: ILUMINAÇÃO DO CAMPO DE FUTEBOL, NO BAIRRO CIDADE ALTA I, NO MUNICÍPIO DE MOJUI DOS CAMPOS, NESTE ESTADO. | F187: 45658 | G187: =Tabela1[[#This Row],[valor_contrapartida]]+Tabela1[[#This Row],[valor_orgao]] -> 81204.06 | H187: 1785.03 | I187: 79419.03
A188: SEOP | B188: Muaná | C188: 251/2022 | D188: =RIGHT(lista!$C188,4) -> 2022 | E188: CONSTRUÇÃO E RESTAURAÇÃO DA ORLA DO RIO MOCAJATUBA, NO MUNICÍPIO DE MUANÁ, NESTE ESTADO | F188: 45837 | G188: =Tabela1[[#This Row],[valor_contrapartida]]+Tabela1[[#This Row],[valor_orgao]] -> 6006919.8 | H188: 240276.8 | I188: 5766643
A189: SEOP | B189: Nova Esperança Do Piriá | C189: 009/2022 | D189: =RIGHT(lista!$C189,4) -> 2022 | E189: CONSTRUÇÃO DE PRAÇA MUNICIPAL NO BAIRRO CIDADE NOVA, NO MUNICÍPIO DE NOVA ESPERANÇA DO PIRIÁ. | F189: 45973 | G189: =Tabela1[[#This Row],[valor_contrapartida]]+Tabela1[[#This Row],[valor_orgao]] -> 424135.28 | H189: 24135.28 | I189: 400000
A190: SEOP | B190: Nova Esperança Do Piriá | C190: 148/2022 | D190: =RIGHT(lista!$C190,4) -> 2022 | E190: CONSTRUÇÃO DE UMA QUADRA DE AREIA E AMBIENTE PARA EVENTOS SOCIAIS DA COMUNIDADE "VILA NOVA", NESTE ESTADO | F190: 46203 | G190: =Tabela1[[#This Row],[valor_contrapartida]]+Tabela1[[#This Row],[valor_orgao]] -> 977846.68 | H190: 39113.87 | I190: 938732.81
A191: SEOP | B191: Nova Esperança Do Piriá | C191: 224/2022 | D191: =RIGHT(lista!$C191,4) -> 2022 | E191: CANALIZAÇÃO E CONSTRUÇÃO DA PRAÇA DO LAGO EM NOVA ESPERANÇA DO PIRIÁ, NESTE ESTADO | F191: 46197 | G191: =Tabela1[[#This Row],[valor_contrapartida]]+Tabela1[[#This Row],[valor_orgao]] -> 8863789.8 | H191: 354551.59 | I191: 8509238.2
... A328: SEOP | B328: Xinguara | C328: 023/2022 | D328: =RIGHT(lista!$C328,4) -> 2022 | E328: REVITALIZAÇÃO DA FEIRA MUNICIPAL DE XINGUARA | F328: 45702 | G328: =Tabela1[[#This Row],[valor_contrapartida]]+Tabela1[[#This Row],[valor_orgao]] -> 4828271.5 | H328: 336068.54 | I328: 4492203

Sheet parcelas
A1: numero_convenio | B1: numero_parcela | C1: valor_previsto | D1: situacao | E1: data_pagamento | F1: valor_pago
A2: 090/2022 | B2: 1 | C2: 270000 | D2: PAGA | E2: 44743 | F2: 270000
A3: 090/2022 | B3: 2 | C3: 3763419.7 | D3: PAGA | E3: 45287 | F3: 3763419.7
A4: 090/2022 | B4: 3 | C4: 4433250 | D4: ABERTA
A5: 090/2022 | B5: 4 | C5: 1150506.4 | D5: ABERTA
A6: 090/2022 | B6: 5 | C6: 297163.22 | D6: ABERTA
A7: 247/2022 | B7: 1 | C7: 500000 | D7: PAGA | E7: 44743 | F7: 500000
A8: 247/2022 | B8: 2 | C8: 4750000 | D8: PAGA | E8: 45219 | F8: 4750000
A9: 247/2022 | B9: 3 | C9: 4750000 | D9: PAGA | E9: 45219 | F9: 4750000
A10: 125/2022 | B10: 1 | C10: 149711.74 | D10: PAGA | E10: 44734 | F10: 149711.74
A11: 125/2022 | B11: 2 | C11: 149711.73 | D11: PAGA | E11: 45216 | F11: 149711.73
A12: 126/2022 | B12: 1 | C12: 300000 | D12: PAGA | E12: 44718 | F12: 300000
A13: 126/2022 | B13: 2 | C13: 900000 | D13: PAGA | E13: 45007 | F13: 900000
A14: 126/2022 | B14: 3 | C14: 300000 | D14: ABERTA
A15: 128/2022 | B15: 1 | C15: 187303.84 | D15: PAGA | E15: 44740 | F15: 187303.84
A16: 128/2022 | B16: 2 | C16: 62696.16 | D16: PAGA | E16: 45216 | F16: 62696.16
A17: 043/2024 | B17: 1 | C17: 100000 | D17: PAGA | E17: 45475 | F17: 100000
A18: 043/2024 | B18: 2 | C18: 457536.96 | D18: PAGA | E18: 45994 | F18: 457536.96
A19: 043/2024 | B19: 3 | C19: 457536.96 | D19: ABERTA
A20: 006/2022 | B20: 1 | C20: 332611.12 | D20: PAGA | E20: 45040 | F20: 332611.12
A21: 006/2022 | B21: 2 | C21: 332611.12 | D21: PAGA | E21: 45407 | F21: 332611.12
A22: 006/2022 | B22: 3 | C22: 332611.12 | D22: ABERTA
A23: 089/2022 | B23: 1 | C23: 268201.83 | D23: PAGA | E23: 44734 | F23: 268201.83
A24: 089/2022 | B24: 2 | C24: 752035.17 | D24: PAGA | E24: 45288 | F24: 752035.17
A25: 089/2022 | B25: 3 | C25: 988349.48 | D25: PAGA | E25: 45288 | F25: 988349.48
A26: 089/2022 | B26: 4 | C26: 1070025 | D26: PAGA | E26: 45740 | F26: 1070025
A27: 089/2022 | B27: 5 | C27: 1144553.2 | D27: ABERTA
A28: 089/2022 | B28: 6 | C28: 1096116.4 | D28: ABERTA
A29: 089/2022 | B29: 7 | C29: 607580.62 | D29: ABERTA
A30: 048/2024 | B30: 1 | C30: 100000 | D30: PAGA | E30: 45478 | F30: 100000
A31: 048/2024 | B31: 2 | C31: 300000 | D31: PAGA | E31: 45978 | F31: 300000
A32: 048/2024 | B32: 3 | C32: 300000 | D32: ABERTA
A33: 048/2024 | B33: 4 | C33: 300000 | D33: ABERTA
A34: 049/2022 | B34: 1 | C34: 1704945 | D34: PAGA | E34: 44694 | F34: 1704945
A35: 049/2022 | B35: 2 | C35: 1704945 | D35: PAGA | E35: 44959 | F35: 1704945
A36: 049/2022 | B36: 3 | C36: 1704945 | D36: PAGA | E36: 45120 | F36: 1704945
A37: 049/2022 | B37: 4 | C37: 1704947.2 | D37: PAGA | E37: 45411 | F37: 1704947.2
A38: 012/2022 | B38: 1 | C38: 176210.84 | D38: PAGA | E38: 44629 | F38: 176210.84
A39: 012/2022 | B39: 2 | C39: 176210.85 | D39: PAGA | E39: 45188 | F39: 176210.85
A40: 020/2022 | B40: 1 | C40: 176210.84 | D40: PAGA | E40: 44629 | F40: 176210.84
...

Sheet plano_interno
A1: numero_convenio | B1: plano_interno
A2: 090/2022 | B2: 22DEMGC0245
A3: 247/2022 | B3: 22DEMGC0253
A4: 125/2022 | B4: 22DEMGC0019
A5: 126/2022 | B5: 22DEMGC0005
A6: 128/2022 | B6: 21DEMPC0485
A7: 043/2024 | B7: 22DEMGC0371
A8: 006/2022 | B8: 22DEMPC0085
A9: 089/2022 | B9: 22DEMGC0087
A10: 048/2024 | B10: 23DEMPC0034
A11: 049/2022 | B11: 22DEMGC0093
A12: 012/2022 | B12: 21DEMGC0015
... A354: 022/2024 | B354: 23DEMGC0102
